2023-01-22 18:12:07,553 (40155/MainThread) snowflake.cli.common.util_cli DEBUG       util_cli:706  - Initialized logging. Log file './snowsql_rt.log_bootstrap', Namespaces: ['snowflake.cli', 'snowflake.connector', 'botocore', 'azure', '__main__', 'eventloop', 'sqlexecute']
2023-01-22 18:12:07,554 (40155/MainThread) snowflake.cli.common.util_cli DEBUG       util_cli:725  - cacert?: /var/folders/nx/j12_90_x7dg085j4zfp0_g840000gn/T/_MEIoYwfOg/base_library.zip/cacert.pem, /var/folders/nx/j12_90_x7dg085j4zfp0_g840000gn/T/_MEIoYwfOg/base_library.zip/certifi/cacert.pem
2023-01-22 18:12:07,554 (40155/MainThread) snowflake.cli.common.util_cli DEBUG       util_cli:725  - cacert?: /var/folders/nx/j12_90_x7dg085j4zfp0_g840000gn/T/_MEIoYwfOg/lib-dynload/cacert.pem, /var/folders/nx/j12_90_x7dg085j4zfp0_g840000gn/T/_MEIoYwfOg/lib-dynload/certifi/cacert.pem
2023-01-22 18:12:07,554 (40155/MainThread) snowflake.cli.common.util_cli DEBUG       util_cli:725  - cacert?: /var/folders/nx/j12_90_x7dg085j4zfp0_g840000gn/T/_MEIoYwfOg/cacert.pem, /var/folders/nx/j12_90_x7dg085j4zfp0_g840000gn/T/_MEIoYwfOg/certifi/cacert.pem
2023-01-22 18:12:07,554 (40155/MainThread) snowflake.cli.common.util_cli INFO       util_cli:733  - cacert.pem is set to REQUESTS_CA_BUNDLE: /var/folders/nx/j12_90_x7dg085j4zfp0_g840000gn/T/_MEIoYwfOg/certifi/cacert.pem
2023-01-22 18:12:07,554 (40155/MainThread) __main__ DEBUG      bootstrap:345  - proxy_host:None, proxy_port: None, proxy_user: None, proxy_password:False
2023-01-22 18:12:07,554 (40155/MainThread) __main__ INFO      bootstrap:350  - no autoupgrade option: False
2023-01-22 18:12:07,554 (40155/MainThread) __main__ INFO      bootstrap:352  - version: None, ret_options: None
2023-01-22 18:12:07,555 (40155/MainThread) __main__ DEBUG      bootstrap:750  - No deletion happened. The number of snowsql is still less than 5
2023-01-22 18:12:07,556 (40155/MainThread) __main__ DEBUG      bootstrap:365  - can we upgrade?: True
2023-01-22 18:12:07,556 (40155/MainThread) __main__ INFO      bootstrap:370  - auto upgrade without version
2023-01-22 18:12:07,556 (40155/MainThread) __main__ DEBUG      bootstrap:906  - Checking Repository: https://sfc-repo.snowflakecomputing.com/snowsql/1.2/darwin_x86_64/index.json
2023-01-22 18:12:54,458 (40155/MainThread) __main__ DEBUG      bootstrap:916  - Failed to list the available snowsql files in remote: https://sfc-repo.snowflakecomputing.com/snowsql/1.2/darwin_x86_64/index.json, HTTPSConnectionPool(host='sfc-repo.snowflakecomputing.com', port=443): Max retries exceeded with url: /snowsql/1.2/darwin_x86_64/index.json (Caused by NewConnectionError('<urllib3.connection.VerifiedHTTPSConnection object at 0x7ff5703e4b80>: Failed to establish a new connection: [Errno 8] nodename nor servname provided, or not known'))
Traceback (most recent call last):
  File "urllib3/connection.py", line 158, in _new_conn
  File "urllib3/util/connection.py", line 57, in create_connection
  File "socket.py", line 918, in getaddrinfo
socket.gaierror: [Errno 8] nodename nor servname provided, or not known

During handling of the above exception, another exception occurred:

Traceback (most recent call last):
  File "urllib3/connectionpool.py", line 597, in urlopen
  File "urllib3/connectionpool.py", line 343, in _make_request
  File "urllib3/connectionpool.py", line 839, in _validate_conn
  File "urllib3/connection.py", line 301, in connect
  File "urllib3/connection.py", line 167, in _new_conn
urllib3.exceptions.NewConnectionError: <urllib3.connection.VerifiedHTTPSConnection object at 0x7ff5703e4b80>: Failed to establish a new connection: [Errno 8] nodename nor servname provided, or not known

During handling of the above exception, another exception occurred:

Traceback (most recent call last):
  File "requests/adapters.py", line 489, in send
  File "urllib3/connectionpool.py", line 637, in urlopen
  File "urllib3/util/retry.py", line 399, in increment
urllib3.exceptions.MaxRetryError: HTTPSConnectionPool(host='sfc-repo.snowflakecomputing.com', port=443): Max retries exceeded with url: /snowsql/1.2/darwin_x86_64/index.json (Caused by NewConnectionError('<urllib3.connection.VerifiedHTTPSConnection object at 0x7ff5703e4b80>: Failed to establish a new connection: [Errno 8] nodename nor servname provided, or not known'))

During handling of the above exception, another exception occurred:

Traceback (most recent call last):
  File "bootstrap.py", line 908, in list_snowsql_files
  File "requests/api.py", line 73, in get
  File "requests/api.py", line 59, in request
  File "requests/sessions.py", line 587, in request
  File "requests/sessions.py", line 701, in send
  File "requests/adapters.py", line 565, in send
requests.exceptions.ConnectionError: HTTPSConnectionPool(host='sfc-repo.snowflakecomputing.com', port=443): Max retries exceeded with url: /snowsql/1.2/darwin_x86_64/index.json (Caused by NewConnectionError('<urllib3.connection.VerifiedHTTPSConnection object at 0x7ff5703e4b80>: Failed to establish a new connection: [Errno 8] nodename nor servname provided, or not known'))
2023-01-22 18:12:54,462 (40155/MainThread) __main__ DEBUG      bootstrap:426  - checking /Applications/SnowSQL.app/Contents/MacOS/ for the snowsql zip file.
2023-01-22 18:12:54,463 (40155/MainThread) __main__ DEBUG      bootstrap:456  - extracting the snowsql zip file. source file: /Applications/SnowSQL.app/Contents/MacOS/snowsql-1.2.24-darwin_x86_64.zip, target dir: /Users/james/.snowsql/1.2.24
2023-01-22 18:12:54,531 (40155/MainThread) __main__ INFO      bootstrap:465  - Verified the signature
2023-01-22 18:12:54,733 (40155/MainThread) __main__ DEBUG      bootstrap:623  - Latest version: 1.2.24 in remote
2023-01-22 18:12:54,736 (40155/MainThread) __main__ INFO      bootstrap:247  - Recorded autoupgrade status
2023-01-22 18:12:54,736 (40155/MainThread) __main__ DEBUG      bootstrap:828  - Running /Users/james/.snowsql/1.2.24/snowsql
